<?xml version = "1.0"?>
<robot name="Part2" xmlns:xacro="http://www.ros.org/wiki/xacro">

<xacro:property name="armyaml" value = "$(find homework2)/config/arm.yaml" />
<xacro:property name="arm" value = '${load_yaml (armyaml)}'/>
<xacro:property name="L1" value="${arm['L1']}"/>
<xacro:property name="L2" value="${arm['L2']}"/>
<xacro:property name="R1" value="${arm['R1']}"/>
<xacro:property name="R2" value="${arm['R2']}"/>

<link name="base">
  <visual>
    <origin xyz="0 0 0" rpy="0 1.571 0" />
    <geometry>
     <sphere radius="0.1" />
    </geometry>
    <material name="green_mat">
      <color rgba="0 1 0 1" />
    </material>
  </visual>
  
  <collision>
    <origin xyz="0 0 0" rpy="0 1.571 0" />
   <geometry>
    <sphere radius="0.1" />
   </geometry>
  </collision>
</link>

<joint name="joint_1" type="continuous">
  <parent link="base" />
  <child link="L1" />
  <axis xyz = "0 0 1" />
  <origin xyz=".1 0 0" rpy="0 0 0" />
</joint>

<link name="L1">
  <visual>
   <inertial>
     <origin xyz=".5 0 0" rpy="0 1.571 0"/>
     <mass value="1"/>
     <inertia ixx="100"  ixy="0"  ixz="0" iyy="100" iyz="0" izz="100" />
   </inertial>
  

   <origin xyz="${L1/2} 0 0" rpy="0 1.571 0" />
   <geometry>
     <cylinder radius="${R1}" length="${L1}" />
   </geometry>
     <material name="blue_mat">
         <color rgba="0 0 1 1" />
     </material>
  </visual>

  <collision>
     <origin xyz="${L1/2} 0 0" rpy="0 1.571 0" />
   <geometry>
     <cylinder radius="${R1}" length="${L1}" />
   </geometry>
  </collision>

</link>

<joint name="joint_2" type="continuous">
  <parent link="L1" />
  <child link="L2" />
  <axis xyz = "0 0 1" />
  <origin xyz="${L1} 0 0" rpy="0 0 0" />
</joint>

<link name="L2">
   <visual>
   <inertial>
     <origin xyz="${L2/2} 0 0" rpy="0 1.571 0"/>
     <mass value="1"/>
     <inertia ixx="100"  ixy="0"  ixz="0" iyy="100" iyz="0" izz="100" />
   </inertial>


  
  <origin xyz="${L2/2} 0 0" rpy="0 1.571 0" />
   <geometry>
     <cylinder radius="${R2}" length="${L2}" />
   </geometry>
     <material name="red_mat">
         <color rgba="1 0 0 1" />
     </material>
  </visual>

  <collision>
     <origin xyz="${L2/2} 0 0" rpy="0 1.571 0" />
  <geometry>
     <cylinder radius="${R2}" length="${L2}" />
  </geometry>
  </collision>  

</link>

<joint name="end_joint" type="fixed">
  <parent link="L2" />
  <child link="end" />
  <axis xyz = "0 0 1" />
  <origin xyz="${L2} 0 0" rpy="0 0 0" />
</joint>

<link name="end">
  <visual>
  <origin xyz=".05 0 0" rpy="0 1.571 0" />
   <geometry>
     <cylinder radius=".1" length=".1" />
   </geometry>
    <material name="invisible">
      <color rgba="0 .5 .5 0" />
    </material>
  </visual>
</link>

</robot>